bring Err

fun getError() -> int, Err::Result {
  return 2, new Err::Result("Error")
}

const num: int, err: Err::Result = getError()

print(num)
print(err.message)

class A {
  init() -> nthg {
  }


  print() -> nthg {
    print("A")
  }


}
const a: A = new A()
a.print()
/; fun test2(a: int, b: str, c = 2.2) -> nthg {
  /;   print("A ", a, "\n")
  /;   print("B ", b, "\n")
  /;   print("C ", c, "\n")
  /; }

/; test2(2, "3", "Hello")
  /; test2(2, "3", 2)
  /; test2(2, "3", 3.5d)
  /; test2(2, "3", 3.5)
  /; test2(2, "3", true)
  /; test2(2, "3", false)

